Workbook

Sheet Messages
A1: recording_id | B1: platform | C1: message_id | D1: author | E1: recipient | F1: direction | G1: t_mmss | H1: t_sent | I1: t_received | J1: message_type | K1: language | L1: text
A2: 004FELI-04-001 | B2: WhatsApp | C2: 1 | D2: Felicitas Albrecht | E2: Gruppe: Albrecht | F2: outgoing | G2: 00:00:48.816 | H2: =IF( F2<>"outgoing", "", TEXT( _xlfn.XLOOKUP(A2,Time!A:A,Time!C:C)+ ( TIMEVALUE(LEFT(G2,8))+(MID(G2,10,3)/86400000) - ( TIMEVALUE(LEFT(_xlfn.XLOOKUP(A2,Time!A:A,Time!B:B),8))+ (MID(_xlfn.XLOOKUP(A2,Time!A:A,Time!B:B),10,3)/86400000) ) ), "hh:mm:ss" ) ) -> 10:01:24 | J2: Text; Emoji | K2: DE | L2: Na schneechaos in ORTSNAME? Ich bin mit meinem bombtrack an die Uni fahren und kann den Schnee problemlos trotzen ⚡️⚡️⚡️
A3: 004FELI-04-002 | B3: WhatsApp | C3: 2 | D3: Tina Albrecht | E3: Gruppe: Albrecht | F3: incoming | H3: =IF( F3<>"outgoing", "", TEXT( _xlfn.XLOOKUP(A3,Time!A:A,Time!C:C)+ ( TIMEVALUE(LEFT(G3,8))+(MID(G3,10,3)/86400000) - ( TIMEVALUE(LEFT(_xlfn.XLOOKUP(A3,Time!A:A,Time!B:B),8))+ (MID(_xlfn.XLOOKUP(A3,Time!A:A,Time!B:B),10,3)/86400000) ) ), "hh:mm:ss" ) ) | I3: 0.41805556 | J3: Bild; Text | K3: DE | L3: Mir gefällt es
A4: 004FELI-04-002 | B4: WhatsApp | C4: 3 | D4: Bert Albrecht | E4: Gruppe: Albrecht | F4: incoming | H4: =IF( F4<>"outgoing", "", TEXT( _xlfn.XLOOKUP(A4,Time!A:A,Time!C:C)+ ( TIMEVALUE(LEFT(G4,8))+(MID(G4,10,3)/86400000) - ( TIMEVALUE(LEFT(_xlfn.XLOOKUP(A4,Time!A:A,Time!B:B),8))+ (MID(_xlfn.XLOOKUP(A4,Time!A:A,Time!B:B),10,3)/86400000) ) ), "hh:mm:ss" ) ) | I4: 0.41805556 | J4: Text; Emoticon | K4: DE | L4: Mir nicht!!!:-/
A5: 004FELI-04-002 | B5: WhatsApp | C5: 4 | D5: Bert Albrecht | E5: Gruppe: Albrecht | F5: incoming | H5: =IF( F5<>"outgoing", "", TEXT( _xlfn.XLOOKUP(A5,Time!A:A,Time!C:C)+ ( TIMEVALUE(LEFT(G5,8))+(MID(G5,10,3)/86400000) - ( TIMEVALUE(LEFT(_xlfn.XLOOKUP(A5,Time!A:A,Time!B:B),8))+ (MID(_xlfn.XLOOKUP(A5,Time!A:A,Time!B:B),10,3)/86400000) ) ), "hh:mm:ss" ) ) | I5: 0.41875 | J5: Text | K5: DE | L5: Pass gut auf!!! Es ist die weiße Hölle!!!
A6: 004FELI-04-002 | B6: WhatsApp | C6: 5 | D6: Felicitas Albrecht | E6: Gruppe: Albrecht | F6: outgoing | G6: 00:00:15.729 | H6: =IF( F6<>"outgoing", "", TEXT( _xlfn.XLOOKUP(A6,Time!A:A,Time!C:C)+ ( TIMEVALUE(LEFT(G6,8))+(MID(G6,10,3)/86400000) - ( TIMEVALUE(LEFT(_xlfn.XLOOKUP(A6,Time!A:A,Time!B:B),8))+ (MID(_xlfn.XLOOKUP(A6,Time!A:A,Time!B:B),10,3)/86400000) ) ), "hh:mm:ss" ) ) -> 10:15:12 | J6: Text | K6: DE | L6: Ich hasse es auch
A7: 004FELI-04-003 | B7: WhatsApp | C7: 6 | D7: Tina Albrecht | E7: Gruppe: Albrecht | F7: incoming | H7: =IF( F7<>"outgoing", "", TEXT( _xlfn.XLOOKUP(A7,Time!A:A,Time!C:C)+ ( TIMEVALUE(LEFT(G7,8))+(MID(G7,10,3)/86400000) - ( TIMEVALUE(LEFT(_xlfn.XLOOKUP(A7,Time!A:A,Time!B:B),8))+ (MID(_xlfn.XLOOKUP(A7,Time!A:A,Time!B:B),10,3)/86400000) ) ), "hh:mm:ss" ) ) | I7: 0.42777778 | J7: Text | K7: DE | L7: Ihr könnt ja eine Volksabstimmung zur Abschaffung des Winters anregen
A8: 004FELI-04-003 | B8: WhatsApp | C8: 7 | D8: Felicitas Albrecht | E8: Gruppe: Albrecht | F8: outgoing | G8: 00:00:06.294 | H8: =IF( F8<>"outgoing", "", TEXT( _xlfn.XLOOKUP(A8,Time!A:A,Time!C:C)+ ( TIMEVALUE(LEFT(G8,8))+(MID(G8,10,3)/86400000) - ( TIMEVALUE(LEFT(_xlfn.XLOOKUP(A8,Time!A:A,Time!B:B),8))+ (MID(_xlfn.XLOOKUP(A8,Time!A:A,Time!B:B),10,3)/86400000) ) ), "hh:mm:ss" ) ) -> 10:28:03 | J8: Text | K8: DE | L8: Au ja
A9: 004FELI-04-004 | B9: WhatsApp | C9: 8 | D9: Tina Albrecht | E9: Gruppe: Albrecht | F9: incoming | H9: =IF( F9<>"outgoing", "", TEXT( _xlfn.XLOOKUP(A9,Time!A:A,Time!C:C)+ ( TIMEVALUE(LEFT(G9,8))+(MID(G9,10,3)/86400000) - ( TIMEVALUE(LEFT(_xlfn.XLOOKUP(A9,Time!A:A,Time!B:B),8))+ (MID(_xlfn.XLOOKUP(A9,Time!A:A,Time!B:B),10,3)/86400000) ) ), "hh:mm:ss" ) ) | I9: 0.43680556 | J9: Emoji | K9: Multimodal | L9: 🤦‍♀️🧑‍🎄
A10: 004FELI-04-005 | B10: Instagram | C10: 9 | D10: Bert Albrecht | E10: Felicitas Albrecht | F10: incoming | H10: =IF( F10<>"outgoing", "", TEXT( _xlfn.XLOOKUP(A10,Time!A:A,Time!C:C)+ ( TIMEVALUE(LEFT(G10,8))+(MID(G10,10,3)/86400000) - ( TIMEVALUE(LEFT(_xlfn.XLOOKUP(A10,Time!A:A,Time!B:B),8))+ (MID(_xlfn.XLOOKUP(A10,Time!A:A,Time!B:B),10,3)/86400000) ) ), "hh:mm:ss" ) ) | I10: 0.56597222 | J10: Video | K10: DE
A11: 004FELI-04-005 | B11: Instagram | C11: 10 | D11: Felicitas Albrecht | E11: Bert Albrecht | F11: outgoing | G11: 00:01:04.831 | H11: =IF( F11<>"outgoing", "", TEXT( _xlfn.XLOOKUP(A11,Time!A:A,Time!C:C)+ ( TIMEVALUE(LEFT(G11,8))+(MID(G11,10,3)/86400000) - ( TIMEVALUE(LEFT(_xlfn.XLOOKUP(A11,Time!A:A,Time!B:B),8))+ (MID(_xlfn.XLOOKUP(A11,Time!A:A,Time!B:B),10,3)/86400000) ) ), "hh:mm:ss" ) ) -> 13:54:26 | J11: Reaktion | K11: Multimodal | L11: ❤️
A12: 004FELI-04-006 | B12: WhatsApp | C12: 11 | D12: André Taber | E12: Felicitas Albrecht | F12: incoming | H12: =IF( F12<>"outgoing", "", TEXT( _xlfn.XLOOKUP(A12,Time!A:A,Time!C:C)+ ( TIMEVALUE(LEFT(G12,8))+(MID(G12,10,3)/86400000) - ( TIMEVALUE(LEFT(_xlfn.XLOOKUP(A12,Time!A:A,Time!B:B),8))+ (MID(_xlfn.XLOOKUP(A12,Time!A:A,Time!B:B),10,3)/86400000) ) ), "hh:mm:ss" ) ) | I12: 0.70694444 | J12: Text | K12: DE | L12: Bin ne Stunde auf der Rolle. Wenn ich danach noch lebe Kaffee ?
A13: 004FELI-04-006 | B13: WhatsApp | C13: 12 | D13: Felicitas Albrecht | E13: André Taber | F13: outgoing | G13: 00:00:24.340 | H13: =IF( F13<>"outgoing", "", TEXT( _xlfn.XLOOKUP(A13,Time!A:A,Time!C:C)+ ( TIMEVALUE(LEFT(G13,8))+(MID(G13,10,3)/86400000) - ( TIMEVALUE(LEFT(_xlfn.XLOOKUP(A13,Time!A:A,Time!B:B),8))+ (MID(_xlfn.XLOOKUP(A13,Time!A:A,Time!B:B),10,3)/86400000) ) ), "hh:mm:ss" ) ) -> 17:01:54 | J13: Text | K13: DE | L13: Jo. Bei dir?
A14: 004FELI-04-006 | B14: WhatsApp | C14: 13 | D14: Felicitas Albrecht | E14: André Taber | F14: unsent | G14: 00:00:30.421 | H14: 0.70972222 | J14: Text | K14: DE | L14: Und wann wä
A15: 004FELI-04-006 | B15: WhatsApp | C15: 14 | D15: Bert Albrecht | E15: Felicitas Albrecht | F15: incoming | H15: =IF( F15<>"outgoing", "", TEXT( _xlfn.XLOOKUP(A15,Time!A:A,Time!C:C)+ ( TIMEVALUE(LEFT(G15,8))+(MID(G15,10,3)/86400000) - ( TIMEVALUE(LEFT(_xlfn.XLOOKUP(A15,Time!A:A,Time!B:B),8))+ (MID(_xlfn.XLOOKUP(A15,Time!A:A,Time!B:B),10,3)/86400000) ) ), "hh:mm:ss" ) ) | I15: 0.70902778 | J15: Bild; Text | K15: DE | L15: Unverzichtbare Adventsartikel
A16: 004FELI-04-006 | B16: WhatsApp | C16: 15 | D16: Felicitas Albrecht | E16: Bert Albrecht | F16: outgoing | G16: 00:00:55.483 | H16: =IF( F16<>"outgoing", "", TEXT( _xlfn.XLOOKUP(A16,Time!A:A,Time!C:C)+ ( TIMEVALUE(LEFT(G16,8))+(MID(G16,10,3)/86400000) - ( TIMEVALUE(LEFT(_xlfn.XLOOKUP(A16,Time!A:A,Time!B:B),8))+ (MID(_xlfn.XLOOKUP(A16,Time!A:A,Time!B:B),10,3)/86400000) ) ), "hh:mm:ss" ) ) -> 17:02:25 | J16: Text | K16: DE | L16: Unverzichtbarer!!
A17: 004FELI-04-006 | B17: WhatsApp | C17: 16 | D17: Bert Albrecht | E17: Felicitas Albrecht | F17: incoming | H17: =IF( F17<>"outgoing", "", TEXT( _xlfn.XLOOKUP(A17,Time!A:A,Time!C:C)+ ( TIMEVALUE(LEFT(G17,8))+(MID(G17,10,3)/86400000) - ( TIMEVALUE(LEFT(_xlfn.XLOOKUP(A17,Time!A:A,Time!B:B),8))+ (MID(_xlfn.XLOOKUP(A17,Time!A:A,Time!B:B),10,3)/86400000) ) ), "hh:mm:ss" ) ) | I17: 0.70972222 | J17: Text | K17: DE | L17: Wollen wir uns morgen mittags kurz treffen Zwecks der Übergabe?
A18: 004FELI-04-006 | B18: WhatsApp | C18: 17 | D18: Felicitas Albrecht | E18: Bert Albrecht | F18: outgoing | G18: 00:01:03.365 | H18: =IF( F18<>"outgoing", "", TEXT( _xlfn.XLOOKUP(A18,Time!A:A,Time!C:C)+ ( TIMEVALUE(LEFT(G18,8))+(MID(G18,10,3)/86400000) - ( TIMEVALUE(LEFT(_xlfn.XLOOKUP(A18,Time!A:A,Time!B:B),8))+ (MID(_xlfn.XLOOKUP(A18,Time!A:A,Time!B:B),10,3)/86400000) ) ), "hh:mm:ss" ) ) -> 17:02:33 | J18: Text | K18: DE | L18: Gern
A19: 004FELI-04-006 | B19: WhatsApp | C19: 18 | D19: Felicitas Albrecht | E19: Bert Albrecht | F19: unsent | G19: 00:01:05.756 | H19: 0.71013889 | J19: Text | K19: DE | L19: Näheres
A20: 004FELI-04-006 | B20: WhatsApp | C20: 19 | D20: Felicitas Albrecht | E20: Bert Albrecht | F20: outgoing | G20: 00:01:08.601 | H20: =IF( F20<>"outgoing", "", TEXT( _xlfn.XLOOKUP(A20,Time!A:A,Time!C:C)+ ( TIMEVALUE(LEFT(G20,8))+(MID(G20,10,3)/86400000) - ( TIMEVALUE(LEFT(_xlfn.XLOOKUP(A20,Time!A:A,Time!B:B),8))+ (MID(_xlfn.XLOOKUP(A20,Time!A:A,Time!B:B),10,3)/86400000) ) ), "hh:mm:ss" ) ) -> 17:02:38 | J20: Emoticon | K20: Multimodal | L20: :)
A21: 004FELI-04-006 | B21: WhatsApp | C21: 20 | D21: Felicitas Albrecht | E21: André Taber | F21: outgoing | G21: 00:01:32.649 | H21: =IF( F21<>"outgoing", "", TEXT( _xlfn.XLOOKUP(A21,Time!A:A,Time!C:C)+ ( TIMEVALUE(LEFT(G21,8))+(MID(G21,10,3)/86400000) - ( TIMEVALUE(LEFT(_xlfn.XLOOKUP(A21,Time!A:A,Time!B:B),8))+ (MID(_xlfn.XLOOKUP(A21,Time!A:A,Time!B:B),10,3)/86400000) ) ), "hh:mm:ss" ) ) -> 17:03:02 | J21: Text | K21: DE | L21: Machen wir 18.30? Da kann ich auch noch 30 min auf die Rolle
A22: 004FELI-04-006 | B22: WhatsApp | C22: 21 | D22: Bert Albrecht | E22: Felicitas Albrecht | F22: incoming | H22: =IF( F22<>"outgoing", "", TEXT( _xlfn.XLOOKUP(A22,Time!A:A,Time!C:C)+ ( TIMEVALUE(LEFT(G22,8))+(MID(G22,10,3)/86400000) - ( TIMEVALUE(LEFT(_xlfn.XLOOKUP(A22,Time!A:A,Time!B:B),8))+ (MID(_xlfn.XLOOKUP(A22,Time!A:A,Time!B:B),10,3)/86400000) ) ), "hh:mm:ss" ) ) | I22: 0.70972222 | J22: Text | K22: DE | L22: Wann past es?
A23: 004FELI-04-006 | B23: WhatsApp | C23: 22 | D23: Felicitas Albrecht | E23: Bert Albrecht | F23: outgoing | G23: 00:01:44.310 | H23: =IF( F23<>"outgoing", "", TEXT( _xlfn.XLOOKUP(A23,Time!A:A,Time!C:C)+ ( TIMEVALUE(LEFT(G23,8))+(MID(G23,10,3)/86400000) - ( TIMEVALUE(LEFT(_xlfn.XLOOKUP(A23,Time!A:A,Time!B:B),8))+ (MID(_xlfn.XLOOKUP(A23,Time!A:A,Time!B:B),10,3)/86400000) ) ), "hh:mm:ss" ) ) -> 17:03:14 | J23: Text | K23: DE | L23: So 13,14?
A24: 004FELI-04-007 | B24: WhatsApp | C24: 23 | D24: Bert Albrecht | E24: Felicitas Albrecht | F24: incoming | H24: =IF( F24<>"outgoing", "", TEXT( _xlfn.XLOOKUP(A24,Time!A:A,Time!C:C)+ ( TIMEVALUE(LEFT(G24,8))+(MID(G24,10,3)/86400000) - ( TIMEVALUE(LEFT(_xlfn.XLOOKUP(A24,Time!A:A,Time!B:B),8))+ (MID(_xlfn.XLOOKUP(A24,Time!A:A,Time!B:B),10,3)/86400000) ) ), "hh:mm:ss" ) ) | I24: 0.71041667 | J24: Text; Emoji | K24: DE | L24: Okay dann 13 Uhr 🕐
A25: 004FELI-04-007 | B25: WhatsApp | C25: 24 | D25: Felicitas Albrecht | E25: Bert Albrecht | F25: outgoing | H25: 0.71180556 | J25: Text | K25: DE | L25: Supi freue mich
A26: 004FELI-04-007 | B26: WhatsApp | C26: 25 | D26: Bert Albrecht | E26: Felicitas Albrecht | F26: incoming | H26: =IF( F26<>"outgoing", "", TEXT( _xlfn.XLOOKUP(A26,Time!A:A,Time!C:C)+ ( TIMEVALUE(LEFT(G26,8))+(MID(G26,10,3)/86400000) - ( TIMEVALUE(LEFT(_xlfn.XLOOKUP(A26,Time!A:A,Time!B:B),8))+ (MID(_xlfn.XLOOKUP(A26,Time!A:A,Time!B:B),10,3)/86400000) ) ), "hh:mm:ss" ) ) | I26: 0.7125 | J26: Emoticon | K26: DE | L26: :-)
A27: 004FELI-04-007 | B27: WhatsApp | C27: 26 | D27: Bert Albrecht | E27: Felicitas Albrecht | F27: incoming | H27: =IF( F27<>"outgoing", "", TEXT( _xlfn.XLOOKUP(A27,Time!A:A,Time!C:C)+ ( TIMEVALUE(LEFT(G27,8))+(MID(G27,10,3)/86400000) - ( TIMEVALUE(LEFT(_xlfn.XLOOKUP(A27,Time!A:A,Time!B:B),8))+ (MID(_xlfn.XLOOKUP(A27,Time!A:A,Time!B:B),10,3)/86400000) ) ), "hh:mm:ss" ) ) | I27: 0.7125 | J27: Text | K27: DE | L27: Biste noch an der Uni?
A28: 004FELI-04-007 | B28: WhatsApp | C28: 27 | D28: Felicitas Albrecht | E28: Bert Albrecht | F28: outgoing | G28: 00:00:14.450 | H28: =IF( F28<>"outgoing", "", TEXT( _xlfn.XLOOKUP(A28,Time!A:A,Time!C:C)+ ( TIMEVALUE(LEFT(G28,8))+(MID(G28,10,3)/86400000) - ( TIMEVALUE(LEFT(_xlfn.XLOOKUP(A28,Time!A:A,Time!B:B),8))+ (MID(_xlfn.XLOOKUP(A28,Time!A:A,Time!B:B),10,3)/86400000) ) ), "hh:mm:ss" ) ) -> 17:10:00 | J28: Text | K28: DE | L28: Ja ein bisschen noch
A29: 004FELI-04-008 | B29: WhatsApp | C29: 28 | D29: Bert Albrecht | E29: Felicitas Albrecht | F29: incoming | H29: =IF( F29<>"outgoing", "", TEXT( _xlfn.XLOOKUP(A29,Time!A:A,Time!C:C)+ ( TIMEVALUE(LEFT(G29,8))+(MID(G29,10,3)/86400000) - ( TIMEVALUE(LEFT(_xlfn.XLOOKUP(A29,Time!A:A,Time!B:B),8))+ (MID(_xlfn.XLOOKUP(A29,Time!A:A,Time!B:B),10,3)/86400000) ) ), "hh:mm:ss" ) ) | I29: 0.71597222 | J29: Text; Emoji | K29: DE | L29: Pass dann gut Auf Vor allem auf die bösen 🚙 SUV Fahrer…..
A30: 004FELI-04-008 | B30: WhatsApp | C30: 29 | D30: Felicitas Albrecht | E30: Bert Albrecht | F30: outgoing | G30: 00:00:09.704 | H30: =IF( F30<>"outgoing", "", TEXT( _xlfn.XLOOKUP(A30,Time!A:A,Time!C:C)+ ( TIMEVALUE(LEFT(G30,8))+(MID(G30,10,3)/86400000) - ( TIMEVALUE(LEFT(_xlfn.XLOOKUP(A30,Time!A:A,Time!B:B),8))+ (MID(_xlfn.XLOOKUP(A30,Time!A:A,Time!B:B),10,3)/86400000) ) ), "hh:mm:ss" ) ) -> 17:12:47 | J30: Text | K30: DE | L30: Logo
A31: 004FELI-04-008 | B31: WhatsApp | C31: 30 | D31: Felicitas Albrecht | E31: Bert Albrecht | F31: outgoing | G31: 00:00:20.976 | H31: =IF( F31<>"outgoing", "", TEXT( _xlfn.XLOOKUP(A31,Time!A:A,Time!C:C)+ ( TIMEVALUE(LEFT(G31,8))+(MID(G31,10,3)/86400000) - ( TIMEVALUE(LEFT(_xlfn.XLOOKUP(A31,Time!A:A,Time!B:B),8))+ (MID(_xlfn.XLOOKUP(A31,Time!A:A,Time!B:B),10,3)/86400000) ) ), "hh:mm:ss" ) ) -> 17:12:58 | J31: Text; Emoticon | K31: DE | L31: Straßen sind aber frei hier in XX :-)
A32: 004FELI-04-008 | B32: WhatsApp | C32: 31 | D32: Bert Albrecht | E32: Felicitas Albrecht | F32: incoming | H32: =IF( F32<>"outgoing", "", TEXT( _xlfn.XLOOKUP(A32,Time!A:A,Time!C:C)+ ( TIMEVALUE(LEFT(G32,8))+(MID(G32,10,3)/86400000) - ( TIMEVALUE(LEFT(_xlfn.XLOOKUP(A32,Time!A:A,Time!B:B),8))+ (MID(_xlfn.XLOOKUP(A32,Time!A:A,Time!B:B),10,3)/86400000) ) ), "hh:mm:ss" ) ) | I32: 0.71736111 | J32: Text; Emoticon | K32: DE | L32: Uff :-)
A33: 004FELI-04-009 | B33: WhatsApp | C33: 32 | D33: André Taber | E33: Felicitas Albrecht | F33: incoming | H33: =IF( F33<>"outgoing", "", TEXT( _xlfn.XLOOKUP(A33,Time!A:A,Time!C:C)+ ( TIMEVALUE(LEFT(G33,8))+(MID(G33,10,3)/86400000) - ( TIMEVALUE(LEFT(_xlfn.XLOOKUP(A33,Time!A:A,Time!B:B),8))+ (MID(_xlfn.XLOOKUP(A33,Time!A:A,Time!B:B),10,3)/86400000) ) ), "hh:mm:ss" ) ) | I33: 0.72152778 | J33: Text; Emoticon | K33: DE | L33: Lieber unterwegs (:
A34: 004FELI-04-009 | B34: WhatsApp | C34: 33 | D34: Felicitas Albrecht | E34: André Taber | F34: outgoing | G34: 00:00:25.215 | H34: =IF( F34<>"outgoing", "", TEXT( _xlfn.XLOOKUP(A34,Time!A:A,Time!C:C)+ ( TIMEVALUE(LEFT(G34,8))+(MID(G34,10,3)/86400000) - ( TIMEVALUE(LEFT(_xlfn.XLOOKUP(A34,Time!A:A,Time!B:B),8))+ (MID(_xlfn.XLOOKUP(A34,Time!A:A,Time!B:B),10,3)/86400000) ) ), "hh:mm:ss" ) ) -> 17:28:25 | J34: Text; Emoticon | K34: DE | L34: Machen wir :). Ich komm von der Uni, also so 18.15 OrtXXXXXXXXX?
A35: 004FELI-04-010 | B35: WhatsApp | C35: 34 | D35: André Taber | E35: Felicitas Albrecht | F35: incoming | H35: =IF( F35<>"outgoing", "", TEXT( _xlfn.XLOOKUP(A35,Time!A:A,Time!C:C)+ ( TIMEVALUE(LEFT(G35,8))+(MID(G35,10,3)/86400000) - ( TIMEVALUE(LEFT(_xlfn.XLOOKUP(A35,Time!A:A,Time!B:B),8))+ (MID(_xlfn.XLOOKUP(A35,Time!A:A,Time!B:B),10,3)/86400000) ) ), "hh:mm:ss" ) ) | I35: 0.72777778 | J35: Text; Emoticon | L35: Ich sag dir ob ich fit bin (:
A36: 004FELI-04-010 | B36: WhatsApp | C36: 35 | D36: Felicitas Albrecht | E36: André Taber | F36: unsent | G36: 00:00:12.729 | H36: 0.72862269 | J36: Emoji | K36: Multimodal | L36: 🤝
A37: 004FELI-04-010 | B37: WhatsApp | C37: 36 | D37: Felicitas Albrecht | E37: André Taber | F37: outgoing | G37: 00:00:18.856 | H37: =IF( F37<>"outgoing", "", TEXT( _xlfn.XLOOKUP(A37,Time!A:A,Time!C:C)+ ( TIMEVALUE(LEFT(G37,8))+(MID(G37,10,3)/86400000) - ( TIMEVALUE(LEFT(_xlfn.XLOOKUP(A37,Time!A:A,Time!B:B),8))+ (MID(_xlfn.XLOOKUP(A37,Time!A:A,Time!B:B),10,3)/86400000) ) ), "hh:mm:ss" ) ) -> 17:29:19 | J37: Reaktion | K37: Multimodal | L37: 🤝
A38: 004FELI-04-012 | B38: WhatsApp | C38: 37 | D38: André Taber | E38: Felicitas Albrecht | F38: incoming | H38: =IF( F38<>"outgoing", "", TEXT( _xlfn.XLOOKUP(A38,Time!A:A,Time!C:C)+ ( TIMEVALUE(LEFT(G38,8))+(MID(G38,10,3)/86400000) - ( TIMEVALUE(LEFT(_xlfn.XLOOKUP(A38,Time!A:A,Time!B:B),8))+ (MID(_xlfn.XLOOKUP(A38,Time!A:A,Time!B:B),10,3)/86400000) ) ), "hh:mm:ss" ) ) | I38: 0.73611111 | J38: Text | K38: DE | L38: Ich glaube ich passe die Woche. Ich bin gar nicht fit und frustriert.
A39: 004FELI-04-012 | B39: WhatsApp | C39: 38 | D39: Felicitas Albrecht | E39: André Taber | F39: outgoing | G39: 00:01:03.492 | H39: =IF( F39<>"outgoing", "", TEXT( _xlfn.XLOOKUP(A39,Time!A:A,Time!C:C)+ ( TIMEVALUE(LEFT(G39,8))+(MID(G39,10,3)/86400000) - ( TIMEVALUE(LEFT(_xlfn.XLOOKUP(A39,Time!A:A,Time!B:B),8))+ (MID(_xlfn.XLOOKUP(A39,Time!A:A,Time!B:B),10,3)/86400000) ) ), "hh:mm:ss" ) ) -> 17:53:03 | J39: Text | K39: DE | L39: Oh man. Ich versteh dich.
A40: 004FELI-04-013 | B40: WhatsApp | C40: 39 | D40: Felicitas Albrecht | E40: Bert Albrecht | F40: outgoing | G40: 00:00:08.994 | H40: =IF( F40<>"outgoing", "", TEXT( _xlfn.XLOOKUP(A40,Time!A:A,Time!C:C)+ ( TIMEVALUE(LEFT(G40,8))+(MID(G40,10,3)/86400000) - ( TIMEVALUE(LEFT(_xlfn.XLOOKUP(A40,Time!A:A,Time!B:B),8))+ (MID(_xlfn.XLOOKUP(A40,Time!A:A,Time!B:B),10,3)/86400000) ) ), "hh:mm:ss" ) ) -> 18:31:09 | J40: Text; Emoji | K40: DE | L40: Bin zu Hause 🏠
...

Sheet Time
A1: recording_id | B1: anchor_video_time | C1: anchor_clock_time | D1: recording_date
A2: 004FELI-04-001 | B2: 00:00:25.092 | C2: 0.41736111 | D2: 45260
A3: 004FELI-04-002 | B3: 00:00:03.960 | C3: 0.42708333 | D3: 45260
A4: 004FELI-04-003 | B4: 00:00:03.544 | C4: 0.43611111 | D4: 45260
A5: 004FELI-04-005 | B5: 00:00:38.716 | C5: 0.57916667 | D5: 45260
A6: 004FELI-04-006 | B6: 00:00:30.212 | C6: 0.70972222 | D6: 45260
A7: 004FELI-04-007 | B7: 00:00:14.424 | C7: 0.71527778 | D7: 45260
A8: 004FELI-04-008 | B8: 00:00:22.848 | C8: 0.71736111 | D8: 45260
A9: 004FELI-04-009 | B9: 00:00:00.000 | C9: 0.72777778 | D9: 45260
A10: 004FELI-04-010 | B10: 00:00:00.000 | C10: 0.72847222 | D10: 45260
A11: 004FELI-04-012 | B11: 00:00:00.000 | C11: 0.74444444 | D11: 45260
A12: 004FELI-04-013 | B12: 00:00:00.000 | C12: 0.77152778 | D12: 45260
A13: 004FELI-04-014 | B13: 00:00:00.000 | C13: 0.78333333 | D13: 45260
A14: 004FELI-04-017 | B14: 00:00:03.899 | C14: 0.81666667 | D14: 45260
