Workbook

Sheet Messages
A1: recording_id | B1: platform | C1: message_id | D1: author | E1: recipient | F1: direction | G1: t_mmss | H1: t_sent | I1: t_received | J1: message_type | K1: language | L1: text
A2: 004FELI-03-001 | B2: WhatsApp | C2: 1 | D2: André Taber | E2: Felicitas Albrecht | F2: incoming | H2: =IF( F2<>"outgoing", "", TEXT( _xlfn.XLOOKUP(A2,Time!A:A,Time!C:C)+ ( TIMEVALUE(LEFT(G2,8))+(MID(G2,10,3)/86400000) - ( TIMEVALUE(LEFT(_xlfn.XLOOKUP(A2,Time!A:A,Time!B:B),8))+ (MID(_xlfn.XLOOKUP(A2,Time!A:A,Time!B:B),10,3)/86400000) ) ), "hh:mm:ss" ) ) | I2: 0.13263889 | J2: Link | K2: Multimodal | L2: https://www.xxxx.xx/1234/56/schlechte-verlierer-sport-xxxxxxxxxx-fair-play
A3: 004FELI-03-001 | B3: WhatsApp | C3: 2 | D3: André Taber | E3: Felicitas Albrecht | F3: incoming | H3: =IF( F3<>"outgoing", "", TEXT( _xlfn.XLOOKUP(A3,Time!A:A,Time!C:C)+ ( TIMEVALUE(LEFT(G3,8))+(MID(G3,10,3)/86400000) - ( TIMEVALUE(LEFT(_xlfn.XLOOKUP(A3,Time!A:A,Time!B:B),8))+ (MID(_xlfn.XLOOKUP(A3,Time!A:A,Time!B:B),10,3)/86400000) ) ), "hh:mm:ss" ) ) | I3: 0.13263889 | J3: Text | K3: DE | L3: Witzig. Die Kommentare sind (übertrieben) hart. Gibt dem Text eine witzige Subnote
A4: 004FELI-03-001 | B4: WhatsApp | C4: 3 | D4: Tina Albrecht | E4: Felicitas Albrecht | F4: incoming | H4: =IF( F4<>"outgoing", "", TEXT( _xlfn.XLOOKUP(A4,Time!A:A,Time!C:C)+ ( TIMEVALUE(LEFT(G4,8))+(MID(G4,10,3)/86400000) - ( TIMEVALUE(LEFT(_xlfn.XLOOKUP(A4,Time!A:A,Time!B:B),8))+ (MID(_xlfn.XLOOKUP(A4,Time!A:A,Time!B:B),10,3)/86400000) ) ), "hh:mm:ss" ) ) | I4: 0.29861111 | J4: Text | K4: DE | L4: Kiregen wir sicher alles hin
A5: 004FELI-03-001 | B5: WhatsApp | C5: 4 | D5: Felicitas Albrecht | E5: Tina Albrecht | F5: outgoing | G5: 00:00:11.723 | H5: =IF( F5<>"outgoing", "", TEXT( _xlfn.XLOOKUP(A5,Time!A:A,Time!C:C)+ ( TIMEVALUE(LEFT(G5,8))+(MID(G5,10,3)/86400000) - ( TIMEVALUE(LEFT(_xlfn.XLOOKUP(A5,Time!A:A,Time!B:B),8))+ (MID(_xlfn.XLOOKUP(A5,Time!A:A,Time!B:B),10,3)/86400000) ) ), "hh:mm:ss" ) ) -> 07:13:12 | J5: Text | K5: DE | L5: Okidoki
A6: 004FELI-03-002 | B6: WhatsApp | C6: 5 | D6: Felicitas Albrecht | E6: Gruppe: Albrecht | F6: outgoing | G6: 00:00:30.491 | H6: =IF( F6<>"outgoing", "", TEXT( _xlfn.XLOOKUP(A6,Time!A:A,Time!C:C)+ ( TIMEVALUE(LEFT(G6,8))+(MID(G6,10,3)/86400000) - ( TIMEVALUE(LEFT(_xlfn.XLOOKUP(A6,Time!A:A,Time!B:B),8))+ (MID(_xlfn.XLOOKUP(A6,Time!A:A,Time!B:B),10,3)/86400000) ) ), "hh:mm:ss" ) ) -> 14:29:30 | J6: Text | K6: DE | L6: Hey, könntet ihr mich bitte kurz in eure Planungen mit einbeziehen?
A7: 004FELI-03-003 | B7: WhatsApp | C7: 6 | D7: Felicitas Albrecht | E7: Gruppe: Albrecht | F7: outgoing | H7: 0.63611111 | J7: Text | K7: DE | L7: Bin jetzt noch auf der Post
A8: 004FELI-03-003 | B8: WhatsApp | C8: 7 | D8: Felicitas Albrecht | E8: Gruppe: Albrecht | F8: outgoing | G8: 00:00:17.810 | H8: =IF( F8<>"outgoing", "", TEXT( _xlfn.XLOOKUP(A8,Time!A:A,Time!C:C)+ ( TIMEVALUE(LEFT(G8,8))+(MID(G8,10,3)/86400000) - ( TIMEVALUE(LEFT(_xlfn.XLOOKUP(A8,Time!A:A,Time!B:B),8))+ (MID(_xlfn.XLOOKUP(A8,Time!A:A,Time!B:B),10,3)/86400000) ) ), "hh:mm:ss" ) ) -> 15:16:18 | J8: Text | K8: DE | L8: Wann wird es bei euch?
A9: 004FELI-03-004 | B9: WhatsApp | C9: 8 | D9: Tina Albrecht | E9: Felicitas Albrecht | F9: incoming | H9: =IF( F9<>"outgoing", "", TEXT( _xlfn.XLOOKUP(A9,Time!A:A,Time!C:C)+ ( TIMEVALUE(LEFT(G9,8))+(MID(G9,10,3)/86400000) - ( TIMEVALUE(LEFT(_xlfn.XLOOKUP(A9,Time!A:A,Time!B:B),8))+ (MID(_xlfn.XLOOKUP(A9,Time!A:A,Time!B:B),10,3)/86400000) ) ), "hh:mm:ss" ) ) | J9: Text | K9: DE | L9: abholen? Sind gleich da
A10: 004FELI-03-004 | B10: WhatsApp | C10: 9 | D10: Tina Albrecht | E10: Felicitas Albrecht | F10: incoming | H10: =IF( F10<>"outgoing", "", TEXT( _xlfn.XLOOKUP(A10,Time!A:A,Time!C:C)+ ( TIMEVALUE(LEFT(G10,8))+(MID(G10,10,3)/86400000) - ( TIMEVALUE(LEFT(_xlfn.XLOOKUP(A10,Time!A:A,Time!B:B),8))+ (MID(_xlfn.XLOOKUP(A10,Time!A:A,Time!B:B),10,3)/86400000) ) ), "hh:mm:ss" ) ) | J10: Text | K10: DE | L10: Oder noch besser: Schnuffiübergabe dort
A11: 004FELI-03-004 | B11: WhatsApp | C11: 10 | D11: Felicitas Albrecht | E11: Tina Albrecht | F11: outgoing | H11: 0.6375 | J11: Text | K11: DE | L11: Ja supi bis gleich
A12: 004FELI-03-004 | B12: WhatsApp | C12: 11 | D12: Felicitas Albrecht | E12: Tina Albrecht | F12: outgoing | H12: 0.6375 | J12: Text | K12: DE | L12: Paar Minuten
A13: 004FELI-03-004 | B13: WhatsApp | C13: 12 | D13: Tina Albrecht | E13: Felicitas Albrecht | F13: incoming | H13: =IF( F13<>"outgoing", "", TEXT( _xlfn.XLOOKUP(A13,Time!A:A,Time!C:C)+ ( TIMEVALUE(LEFT(G13,8))+(MID(G13,10,3)/86400000) - ( TIMEVALUE(LEFT(_xlfn.XLOOKUP(A13,Time!A:A,Time!B:B),8))+ (MID(_xlfn.XLOOKUP(A13,Time!A:A,Time!B:B),10,3)/86400000) ) ), "hh:mm:ss" ) ) | I13: 0.63819444 | J13: Emoji | K13: Multimodal | L13: 👍
A14: 004FELI-03-005 | B14: WhatsApp | C14: 13 | D14: Tina Albrecht | E14: Felicitas Albrecht | F14: incoming | H14: =IF( F14<>"outgoing", "", TEXT( _xlfn.XLOOKUP(A14,Time!A:A,Time!C:C)+ ( TIMEVALUE(LEFT(G14,8))+(MID(G14,10,3)/86400000) - ( TIMEVALUE(LEFT(_xlfn.XLOOKUP(A14,Time!A:A,Time!B:B),8))+ (MID(_xlfn.XLOOKUP(A14,Time!A:A,Time!B:B),10,3)/86400000) ) ), "hh:mm:ss" ) ) | I14: 0.63958333 | J14: Text | K14: DE | L14: Sind da
A15: 004FELI-03-005 | B15: WhatsApp | C15: 14 | D15: Tina Albrecht | E15: Felicitas Albrecht | F15: incoming | H15: =IF( F15<>"outgoing", "", TEXT( _xlfn.XLOOKUP(A15,Time!A:A,Time!C:C)+ ( TIMEVALUE(LEFT(G15,8))+(MID(G15,10,3)/86400000) - ( TIMEVALUE(LEFT(_xlfn.XLOOKUP(A15,Time!A:A,Time!B:B),8))+ (MID(_xlfn.XLOOKUP(A15,Time!A:A,Time!B:B),10,3)/86400000) ) ), "hh:mm:ss" ) ) | I15: 0.64305556 | J15: Text | K15: DE | L15: Papa steht vor der Post
A16: 004FELI-03-005 | B16: WhatsApp | C16: 15 | D16: André Taber | E16: Felicitas Albrecht | F16: incoming | H16: =IF( F16<>"outgoing", "", TEXT( _xlfn.XLOOKUP(A16,Time!A:A,Time!C:C)+ ( TIMEVALUE(LEFT(G16,8))+(MID(G16,10,3)/86400000) - ( TIMEVALUE(LEFT(_xlfn.XLOOKUP(A16,Time!A:A,Time!B:B),8))+ (MID(_xlfn.XLOOKUP(A16,Time!A:A,Time!B:B),10,3)/86400000) ) ), "hh:mm:ss" ) ) | I16: 0.67013889 | J16: Text | K16: DE | L16: Bin heute leider krank ):
A17: 004FELI-03-005 | B17: WhatsApp | C17: 16 | D17: André Taber | E17: Felicitas Albrecht | F17: incoming | H17: =IF( F17<>"outgoing", "", TEXT( _xlfn.XLOOKUP(A17,Time!A:A,Time!C:C)+ ( TIMEVALUE(LEFT(G17,8))+(MID(G17,10,3)/86400000) - ( TIMEVALUE(LEFT(_xlfn.XLOOKUP(A17,Time!A:A,Time!B:B),8))+ (MID(_xlfn.XLOOKUP(A17,Time!A:A,Time!B:B),10,3)/86400000) ) ), "hh:mm:ss" ) ) | I17: 0.67083333 | J17: Text | K17: DE | L17: Du bist sicher nicht vor 18 Uhr raus?
A18: 004FELI-03-005 | B18: WhatsApp | C18: 17 | D18: Felicitas Albrecht | E18: André Taber | F18: outgoing | G18: 00:01:07.399 | H18: =IF( F18<>"outgoing", "", TEXT( _xlfn.XLOOKUP(A18,Time!A:A,Time!C:C)+ ( TIMEVALUE(LEFT(G18,8))+(MID(G18,10,3)/86400000) - ( TIMEVALUE(LEFT(_xlfn.XLOOKUP(A18,Time!A:A,Time!B:B),8))+ (MID(_xlfn.XLOOKUP(A18,Time!A:A,Time!B:B),10,3)/86400000) ) ), "hh:mm:ss" ) ) -> 16:12:34 | J18: Text; Emoticon | K18: DE | L18: Oh je :(
A19: 004FELI-03-005 | B19: WhatsApp | C19: 18 | D19: Felicitas Albrecht | E19: André Taber | F19: outgoing | G19: 00:01:07.411 | H19: =IF( F19<>"outgoing", "", TEXT( _xlfn.XLOOKUP(A19,Time!A:A,Time!C:C)+ ( TIMEVALUE(LEFT(G19,8))+(MID(G19,10,3)/86400000) - ( TIMEVALUE(LEFT(_xlfn.XLOOKUP(A19,Time!A:A,Time!B:B),8))+ (MID(_xlfn.XLOOKUP(A19,Time!A:A,Time!B:B),10,3)/86400000) ) ), "hh:mm:ss" ) ) -> 16:12:34 | J19: Text | K19: DE | L19: Ich hab den Hund und bin deshalb schon zu Hause. Je nach deinem Befinden könnte ich also für Spaziergang/Kaffee trotzdem rum kommen
A20: 004FELI-03-006 | B20: WhatsApp | C20: 19 | D20: Felicitas Albrecht | E20: Gruppe: Albrecht | F20: outgoing | G20: 00:00:30.741 | H20: =IF( F20<>"outgoing", "", TEXT( _xlfn.XLOOKUP(A20,Time!A:A,Time!C:C)+ ( TIMEVALUE(LEFT(G20,8))+(MID(G20,10,3)/86400000) - ( TIMEVALUE(LEFT(_xlfn.XLOOKUP(A20,Time!A:A,Time!B:B),8))+ (MID(_xlfn.XLOOKUP(A20,Time!A:A,Time!B:B),10,3)/86400000) ) ), "hh:mm:ss" ) ) -> 16:23:14 | J20: Text; Emoticon | K20: DE | L20: Könnt euch ein bisschen mehr Zeit lassen, André und ich haben uns vertagt :)
A21: 004FELI-03-007 | B21: Instagram | C21: 20 | D21: Felicitas Albrecht | E21: Tina Albrecht | F21: outgoing | H21: 0.60208333 | J21: Bild | K21: DE
A22: 004FELI-03-007 | B22: Instagram | C22: 21 | D22: Tina Albrecht | E22: Felicitas Albrecht | F22: incoming | H22: =IF( F22<>"outgoing", "", TEXT( _xlfn.XLOOKUP(A22,Time!A:A,Time!C:C)+ ( TIMEVALUE(LEFT(G22,8))+(MID(G22,10,3)/86400000) - ( TIMEVALUE(LEFT(_xlfn.XLOOKUP(A22,Time!A:A,Time!B:B),8))+ (MID(_xlfn.XLOOKUP(A22,Time!A:A,Time!B:B),10,3)/86400000) ) ), "hh:mm:ss" ) ) | I22: 0.64166667 | J22: Text | K22: DE | L22: Oh, da müssen wir unbedingt hin!!
A23: 004FELI-03-007 | B23: Instagram | C23: 22 | D23: Felicitas Albrecht | E23: Tina Albrecht | F23: outgoing | G23: 00:00:07.915 | H23: =IF( F23<>"outgoing", "", TEXT( _xlfn.XLOOKUP(A23,Time!A:A,Time!C:C)+ ( TIMEVALUE(LEFT(G23,8))+(MID(G23,10,3)/86400000) - ( TIMEVALUE(LEFT(_xlfn.XLOOKUP(A23,Time!A:A,Time!B:B),8))+ (MID(_xlfn.XLOOKUP(A23,Time!A:A,Time!B:B),10,3)/86400000) ) ), "hh:mm:ss" ) ) -> 16:24:08 | J23: Emoji | K23: Multimodal | L23: 💯
A24: 004FELI-03-007 | B24: WhatsApp | C24: 23 | D24: Tina Albrecht | E24: Gruppe: Albrecht | F24: incoming | H24: =IF( F24<>"outgoing", "", TEXT( _xlfn.XLOOKUP(A24,Time!A:A,Time!C:C)+ ( TIMEVALUE(LEFT(G24,8))+(MID(G24,10,3)/86400000) - ( TIMEVALUE(LEFT(_xlfn.XLOOKUP(A24,Time!A:A,Time!B:B),8))+ (MID(_xlfn.XLOOKUP(A24,Time!A:A,Time!B:B),10,3)/86400000) ) ), "hh:mm:ss" ) ) | J24: Text | K24: DE | L24: Danke, aber Parkzeit endet 17.20 und wir sind schon zur Hälfte durch
A25: 004FELI-03-007 | B25: WhatsApp | C25: 24 | D25: Felicitas Albrecht | E25: Gruppe: Albrecht | F25: outgoing | G25: 00:00:17.094 | H25: =IF( F25<>"outgoing", "", TEXT( _xlfn.XLOOKUP(A25,Time!A:A,Time!C:C)+ ( TIMEVALUE(LEFT(G25,8))+(MID(G25,10,3)/86400000) - ( TIMEVALUE(LEFT(_xlfn.XLOOKUP(A25,Time!A:A,Time!B:B),8))+ (MID(_xlfn.XLOOKUP(A25,Time!A:A,Time!B:B),10,3)/86400000) ) ), "hh:mm:ss" ) ) -> 16:24:17 | J25: Text | K25: DE | L25: Okayyyyy
A26: 004FELI-03-008 | B26: WhatsApp | C26: 25 | D26: André Taber | E26: Felicitas Albrecht | F26: incoming | H26: =IF( F26<>"outgoing", "", TEXT( _xlfn.XLOOKUP(A26,Time!A:A,Time!C:C)+ ( TIMEVALUE(LEFT(G26,8))+(MID(G26,10,3)/86400000) - ( TIMEVALUE(LEFT(_xlfn.XLOOKUP(A26,Time!A:A,Time!B:B),8))+ (MID(_xlfn.XLOOKUP(A26,Time!A:A,Time!B:B),10,3)/86400000) ) ), "hh:mm:ss" ) ) | I26: 0.68958333 | J26: Text | K26: DE | L26: Jetzt?
A27: 004FELI-03-008 | B27: WhatsApp | C27: 26 | D27: André Taber | E27: Felicitas Albrecht | F27: incoming | H27: =IF( F27<>"outgoing", "", TEXT( _xlfn.XLOOKUP(A27,Time!A:A,Time!C:C)+ ( TIMEVALUE(LEFT(G27,8))+(MID(G27,10,3)/86400000) - ( TIMEVALUE(LEFT(_xlfn.XLOOKUP(A27,Time!A:A,Time!B:B),8))+ (MID(_xlfn.XLOOKUP(A27,Time!A:A,Time!B:B),10,3)/86400000) ) ), "hh:mm:ss" ) ) | I27: 0.68958333 | J27: Text | K27: DE | L27: Oder so in ner halben?
A28: 004FELI-03-008 | B28: WhatsApp | C28: 27 | D28: Felicitas Albrecht | E28: André Taber | F28: outgoing | H28: 0.72222222 | J28: Text; Emoji | K28: DE | L28: Spotify Jahresrückblich ist da⚡️
A29: 004FELI-03-008 | B29: WhatsApp | C29: 28 | D29: Tina Albrecht | E29: Felicitas Albrecht | F29: incoming | I29: 0.68402778 | J29: Emoji | K29: Multimodal | L29: 😘
A30: 004FELI-03-008 | B30: WhatsApp | C30: 29 | D30: Felicitas Albrecht | E30: André Taber | F30: outgoing | G30: 00:00:31.406 | H30: =IF( F30<>"outgoing", "", TEXT( _xlfn.XLOOKUP(A30,Time!A:A,Time!C:C)+ ( TIMEVALUE(LEFT(G30,8))+(MID(G30,10,3)/86400000) - ( TIMEVALUE(LEFT(_xlfn.XLOOKUP(A30,Time!A:A,Time!B:B),8))+ (MID(_xlfn.XLOOKUP(A30,Time!A:A,Time!B:B),10,3)/86400000) ) ), "hh:mm:ss" ) ) -> 17:36:31 | J30: Text; Emoticon | K30: DE | L30: könnte ab jetzt, sonst morgen und Freitag flexibel (abends) :)
A31: 004FELI-03-010 | B31: WhatsApp | C31: 30 | D31: André Taber | E31: Felicitas Albrecht | F31: incoming | H31: =IF( F31<>"outgoing", "", TEXT( _xlfn.XLOOKUP(A31,Time!A:A,Time!C:C)+ ( TIMEVALUE(LEFT(G31,8))+(MID(G31,10,3)/86400000) - ( TIMEVALUE(LEFT(_xlfn.XLOOKUP(A31,Time!A:A,Time!B:B),8))+ (MID(_xlfn.XLOOKUP(A31,Time!A:A,Time!B:B),10,3)/86400000) ) ), "hh:mm:ss" ) ) | I31: 0.73958333 | J31: Text | K31: DE | L31: Schon gesehen. NAME hatte eine persönliche danke Nachricht von tailor swift Fand ich süß
A32: 004FELI-03-010 | B32: WhatsApp | C32: 31 | D32: André Taber | E32: Felicitas Albrecht | F32: incoming | H32: =IF( F32<>"outgoing", "", TEXT( _xlfn.XLOOKUP(A32,Time!A:A,Time!C:C)+ ( TIMEVALUE(LEFT(G32,8))+(MID(G32,10,3)/86400000) - ( TIMEVALUE(LEFT(_xlfn.XLOOKUP(A32,Time!A:A,Time!B:B),8))+ (MID(_xlfn.XLOOKUP(A32,Time!A:A,Time!B:B),10,3)/86400000) ) ), "hh:mm:ss" ) ) | I32: 0.73958333 | J32: Text | K32: DE | L32: Bleibe zu Hause. Gehe morgen sicher zum Arzt
A33: 004FELI-03-010 | B33: WhatsApp | C33: 32 | D33: André Taber | E33: Felicitas Albrecht | F33: outgoing | G33: 00:00:39.650 | H33: =IF( F33<>"outgoing", "", TEXT( _xlfn.XLOOKUP(A33,Time!A:A,Time!C:C)+ ( TIMEVALUE(LEFT(G33,8))+(MID(G33,10,3)/86400000) - ( TIMEVALUE(LEFT(_xlfn.XLOOKUP(A33,Time!A:A,Time!B:B),8))+ (MID(_xlfn.XLOOKUP(A33,Time!A:A,Time!B:B),10,3)/86400000) ) ), "hh:mm:ss" ) ) -> 18:10:59 | J33: Reaktion | K33: Multimodal | L33: 😐
A34: 004FELI-03-010 | B34: WhatsApp | C34: 33 | D34: Felicitas Albrecht | E34: André Taber | F34: outgoing | G34: 00:00:58.983 | H34: =IF( F34<>"outgoing", "", TEXT( _xlfn.XLOOKUP(A34,Time!A:A,Time!C:C)+ ( TIMEVALUE(LEFT(G34,8))+(MID(G34,10,3)/86400000) - ( TIMEVALUE(LEFT(_xlfn.XLOOKUP(A34,Time!A:A,Time!B:B),8))+ (MID(_xlfn.XLOOKUP(A34,Time!A:A,Time!B:B),10,3)/86400000) ) ), "hh:mm:ss" ) ) -> 18:11:19 | J34: Reaktion | K34: Multimodal | L34: 😷
A35: 004FELI-03-010 | B35: WhatsApp | C35: 34 | D35: Felicitas Albrecht | E35: André Taber | F35: outgoing | G35: 00:01:24.325 | H35: =IF( F35<>"outgoing", "", TEXT( _xlfn.XLOOKUP(A35,Time!A:A,Time!C:C)+ ( TIMEVALUE(LEFT(G35,8))+(MID(G35,10,3)/86400000) - ( TIMEVALUE(LEFT(_xlfn.XLOOKUP(A35,Time!A:A,Time!B:B),8))+ (MID(_xlfn.XLOOKUP(A35,Time!A:A,Time!B:B),10,3)/86400000) ) ), "hh:mm:ss" ) ) -> 18:11:44 | J35: Text; Emoji | K35: DE | L35: Johann Sebastian Bach hat mir nix geschrieben 🥺
A36: 004FELI-03-011 | B36: WhatsApp | C36: 35 | D36: André Taber | E36: Felicitas Albrecht | F36: incoming | H36: =IF( F36<>"outgoing", "", TEXT( _xlfn.XLOOKUP(#REF!,Time!A:A,Time!C:C)+ ( TIMEVALUE(LEFT(G36,8))+(MID(G36,10,3)/86400000) - ( TIMEVALUE(LEFT(_xlfn.XLOOKUP(#REF!,Time!A:A,Time!B:B),8))+ (MID(_xlfn.XLOOKUP(#REF!,Time!A:A,Time!B:B),10,3)/86400000) ) ), "hh:mm:ss" ) ) | I36: 0.75763889 | J36: Reaktion | K36: Multimodal | L36: 🎹
A37: 004FELI-03-013 | B37: WhatsApp | C37: 36 | D37: Felicitas Albrecht | E37: Gruppe: Albrecht | F37: outgoing | G37: 00:00:22.842 | H37: =IF( F37<>"outgoing", "", TEXT( _xlfn.XLOOKUP(A37,Time!A:A,Time!C:C)+ ( TIMEVALUE(LEFT(G37,8))+(MID(G37,10,3)/86400000) - ( TIMEVALUE(LEFT(_xlfn.XLOOKUP(A37,Time!A:A,Time!B:B),8))+ (MID(_xlfn.XLOOKUP(A37,Time!A:A,Time!B:B),10,3)/86400000) ) ), "hh:mm:ss" ) ) -> 20:00:57 | J37: Bild; Emoji | K37: Multimodal | L37: 😭
A38: 004FELI-03-014 | B38: WhatsApp | C38: 37 | D38: Tina Albrecht | E38: Gruppe: Albrecht | F38: incoming | H38: =IF( F38<>"outgoing", "", TEXT( _xlfn.XLOOKUP(A38,Time!A:A,Time!C:C)+ ( TIMEVALUE(LEFT(G38,8))+(MID(G38,10,3)/86400000) - ( TIMEVALUE(LEFT(_xlfn.XLOOKUP(A38,Time!A:A,Time!B:B),8))+ (MID(_xlfn.XLOOKUP(A38,Time!A:A,Time!B:B),10,3)/86400000) ) ), "hh:mm:ss" ) ) | I38: 0.83402778 | J38: Text | K38: DE | L38: Ja und?
A39: 004FELI-03-014 | B39: WhatsApp | C39: 38 | D39: Tina Albrecht | E39: Gruppe: Albrecht | F39: incoming | H39: =IF( F39<>"outgoing", "", TEXT( _xlfn.XLOOKUP(A39,Time!A:A,Time!C:C)+ ( TIMEVALUE(LEFT(G39,8))+(MID(G39,10,3)/86400000) - ( TIMEVALUE(LEFT(_xlfn.XLOOKUP(A39,Time!A:A,Time!B:B),8))+ (MID(_xlfn.XLOOKUP(A39,Time!A:A,Time!B:B),10,3)/86400000) ) ), "hh:mm:ss" ) ) | I39: 0.83402778 | J39: Text | K39: DE | L39: Wie busy bist du am Freitag? Könntest du einen AK entgegen nehmen?
A40: 004FELI-03-014 | B40: WhatsApp | C40: 39 | D40: Felicitas Albrecht | E40: Gruppe: Albrecht | F40: outgoing | G40: 00:00:12.145 | H40: =IF( F40<>"outgoing", "", TEXT( _xlfn.XLOOKUP(A40,Time!A:A,Time!C:C)+ ( TIMEVALUE(LEFT(G40,8))+(MID(G40,10,3)/86400000) - ( TIMEVALUE(LEFT(_xlfn.XLOOKUP(A40,Time!A:A,Time!B:B),8))+ (MID(_xlfn.XLOOKUP(A40,Time!A:A,Time!B:B),10,3)/86400000) ) ), "hh:mm:ss" ) ) -> 20:04:12 | J40: Text | K40: DE | L40: Ne man war ein Scherz
...

Sheet Time
A1: recording_id | B1: anchor_video_time | C1: anchor_clock_time | D1: recording_date
A2: 004FELI-03-001 | B2: 00:00:00.000 | C2: 0.30069444 | D2: 45259
A3: 004FELI-03-002 | B3: 00:00:00.000 | C3: 0.60347222 | D3: 45259
A4: 004FELI-03-003 | B4: 00:00:00.000 | C4: 0.63611111 | D4: 45259
A5: 004FELI-03-005 | B5: 00:00:33.426 | C5: 0.675 | D5: 45259
A6: 004FELI-03-006 | B6: 00:00:17.121 | C6: 0.68263889 | D6: 45259
A7: 004FELI-03-007 | B7: 00:00:00.000 | C7: 0.68333333 | D7: 45259
A8: 004FELI-03-008 | B8: 00:00:00.000 | C8: 0.73333333 | D8: 45259
A9: 004FELI-03-010 | B9: 00:00:40.346 | C9: 0.75763889 | D9: 45259
A10: 004FELI-03-013 | B10: 00:00:25.814 | C10: 0.83402778 | D10: 45259
A11: 004FELI-03-014 | B11: 00:01:00.532 | C11: 0.83680556 | D11: 45259
A12: 004FELI-03-015 | B12: 00:00:34.346 | C12: 0.85833333 | D12: 45259
A13: 004FELI-03-017 | B13: 00:00:19.910 | C13: 0.86180556 | D13: 45259
... A16: 004FELI-03-021 | B16: 00:00:00.000 | C16: 0.94513889 | D16: 45259
